<?xml version="1.0" encoding="utf-8"?>
<!-- This URDF was automatically created by SolidWorks to URDF Exporter! Originally created by Stephen Brawner (brawner@gmail.com) 
     Commit Version: 1.5.1-0-g916b5db  Build Version: 1.5.7152.31018
     For more information, please see http://wiki.ros.org/sw_urdf_exporter -->
<robot
  name="Assem6.SLDASM">
  <link
    name="gripper_base">
    <inertial>
      <origin
        xyz="-0.000423874658945828 0.0270489334970193 0.00202069857196371"
        rpy="0 0 0" />
      <mass
        value="0.00483102003103807" />
      <inertia
        ixx="1.38411480569428E-06"
        ixy="-4.00945048304451E-08"
        ixz="8.4005154816795E-15"
        iyy="6.57287988539018E-07"
        iyz="2.96792348290991E-09"
        izz="2.02910792860384E-06" />
    </inertial>
    <visual>
      <origin
        xyz="0 0 0"
        rpy="0 0 0" />
      <geometry>
        <mesh
          filename="package://Assem6.SLDASM/meshes/gripper_base.STL" />
      </geometry>
      <material
        name="">
        <color
          rgba="0.792156862745098 0.819607843137255 0.933333333333333 1" />
      </material>
    </visual>
    <collision>
      <origin
        xyz="0 0 0"
        rpy="0 0 0" />
      <geometry>
        <mesh
          filename="package://Assem6.SLDASM/meshes/gripper_base.STL" />
      </geometry>
    </collision>
  </link>
  <link
    name="gripper_right">
    <inertial>
      <origin
        xyz="-0.00084248815409376 0.00381485121883249 -0.011086056602204"
        rpy="0 0 0" />
      <mass
        value="0.00596550984411769" />
      <inertia
        ixx="9.56112856867454E-07"
        ixy="-4.28298934156437E-24"
        ixz="-3.26863313385363E-23"
        iyy="8.61567214743861E-07"
        iyz="6.04950359157059E-08"
        izz="1.60894551683634E-07" />
    </inertial>
    <visual>
      <origin
        xyz="0 0 0"
        rpy="0 0 0" />
      <geometry>
        <mesh
          filename="package://Assem6.SLDASM/meshes/gripper_right.STL" />
      </geometry>
      <material
        name="">
        <color
          rgba="0.694117647058824 0.0941176470588235 0.0941176470588235 1" />
      </material>
    </visual>
    <collision>
      <origin
        xyz="0 0 0"
        rpy="0 0 0" />
      <geometry>
        <mesh
          filename="package://Assem6.SLDASM/meshes/gripper_right.STL" />
      </geometry>
    </collision>
  </link>
  <joint
    name="right_gripper_joint"
    type="fixed">
    <origin
      xyz="0.0135 -0.003 0.0376"
      rpy="3.1416 0 -1.5708" />
    <parent
      link="gripper_base" />
    <child
      link="gripper_right" />
    <axis
      xyz="0 0 0" />
    <mimic
      joint="left_gripper_joint"
      multiplier="1"
      offset="0" />
  </joint>
  <link
    name="left_gripper">
    <inertial>
      <origin
        xyz="-0.00335779506191281 0.00673686992025581 -0.026881196843319"
        rpy="0 0 0" />
      <mass
        value="0.00383024372678011" />
      <inertia
        ixx="8.70244848187855E-07"
        ixy="-6.6697469096319E-24"
        ixz="1.04854574866522E-23"
        iyy="7.6026358321787E-07"
        iyz="1.41814391699808E-07"
        izz="1.15723781650982E-07" />
    </inertial>
    <visual>
      <origin
        xyz="0 0 0"
        rpy="0 0 0" />
      <geometry>
        <mesh
          filename="package://Assem6.SLDASM/meshes/left_gripper.STL" />
      </geometry>
      <material
        name="">
        <color
          rgba="0.694117647058824 0.0941176470588235 0.0941176470588235 1" />
      </material>
    </visual>
    <collision>
      <origin
        xyz="0 0 0"
        rpy="0 0 0" />
      <geometry>
        <mesh
          filename="package://Assem6.SLDASM/meshes/left_gripper.STL" />
      </geometry>
    </collision>
  </link>
  <joint
    name="left_gripper_joint"
    type="continuous">
    <origin
      xyz="-0.0135 0 0.0376"
      rpy="3.0107 0 1.5708" />
    <parent
      link="gripper_base" />
    <child
      link="left_gripper" />
    <axis
      xyz="1 0 0" />
    <limit
      lower="1.7017"
      upper="3.0107"
      effort="1000"
      velocity="1" />
  </joint>
</robot>